2024-05-22 09:41:45,741 - WARNING - 異常-主軸上方ACM 建議-修整砂輪
2024-05-22 09:42:43,280 - WARNING - 異常-主軸上方ACM 建議-修整砂輪
2024-05-22 09:43:02,747 - WARNING - 異常-主軸上方ACM 建議-修整砂輪
2024-05-22 09:43:20,270 - WARNING - 異常-主軸上方ACM 建議-修整砂輪
2024-05-22 23:41:15,829 - WARNING - 異常-主軸上方ACM 建議-修整砂輪
2024-05-22 23:42:55,585 - WARNING - 異常-主軸上方ACM 建議-修整砂輪
2024-05-22 23:44:43,548 - WARNING - 異常-主軸上方ACM 建議-修整砂輪
2024-05-22 23:45:17,834 - WARNING - 異常-主軸上方ACM 建議-修整砂輪
2024-05-22 23:48:29,202 - WARNING - 異常-主軸上方ACM 建議-修整砂輪
2024-05-22 23:49:37,397 - WARNING - 異常-主軸上方ACM 建議-修整砂輪
2024-05-22 23:50:03,353 - WARNING - 異常-主軸上方ACM 建議-修整砂輪
2024-05-22 23:50:22,526 - WARNING - 異常-主軸上方ACM 建議-修整砂輪
2024-07-22 11:16:44,437 - WARNING - 異常-主軸上方ACM 建議-修整砂輪
2024-07-22 11:16:44,437 - WARNING - 異常-載台CC 建議-修整砂輪
2024-07-23 14:05:14,119 - WARNING - 異常-主軸上方ACM 建議-修整砂輪
2024-07-23 14:05:14,123 - WARNING - 異常-載台CC 建議-修整砂輪
2024-07-23 16:46:00,083 - WARNING - 異常-主軸上方ACM 建議-修整砂輪
2024-07-23 16:46:00,084 - WARNING - 異常-載台CC 建議-修整砂輪
2024-07-23 16:58:20,355 - WARNING - 異常-主軸上方ACM 建議-修整砂輪
2024-07-23 16:58:20,359 - WARNING - 異常-載台CC 建議-修整砂輪
2024-07-23 16:59:36,180 - WARNING - 異常-載台CC 建議-修整砂輪
2024-07-23 16:59:36,182 - WARNING - 異常-主軸上方ACM 建議-修整砂輪
2024-07-23 17:01:28,080 - WARNING - 異常-主軸上方ACM 建議-修整砂輪
2024-07-23 17:01:28,080 - WARNING - 異常-載台CC 建議-修整砂輪
2024-07-23 17:17:42,089 - WARNING - 異常-載台CC 建議-修整砂輪
2024-07-23 17:17:42,090 - WARNING - 異常-主軸上方ACM 建議-修整砂輪
2024-07-23 17:44:19,041 - ERROR - Error processing MQTT message: 'id'
2024-07-23 17:44:19,041 - ERROR - Error processing MQTT message: 'id'
2024-07-27 14:29:50,940 - WARNING - 異常-主軸上方ACM 建議-修整砂輪
2024-07-27 14:29:50,941 - WARNING - 異常-載台CC 建議-修整砂輪
2024-07-27 14:36:38,101 - WARNING - 異常-主軸上方ACM 建議-修整砂輪
2024-07-27 14:36:38,104 - WARNING - 異常-載台CC 建議-修整砂輪
2024-07-27 14:39:06,277 - WARNING - 異常-主軸上方ACM 建議-修整砂輪
2024-07-27 14:39:06,279 - WARNING - 異常-載台CC 建議-修整砂輪
2024-07-27 14:39:36,404 - WARNING - 異常-主軸上方ACM 建議-修整砂輪
2024-07-27 14:39:36,404 - WARNING - 異常-載台CC 建議-修整砂輪
2024-07-27 14:39:47,334 - WARNING - 異常-主軸上方ACM 建議-修整砂輪
2024-07-27 14:39:47,336 - WARNING - 異常-載台CC 建議-修整砂輪
2024-07-27 14:39:52,335 - WARNING - 異常-主軸上方ACM 建議-修整砂輪
2024-07-27 14:39:52,339 - WARNING - 異常-載台CC 建議-修整砂輪
2024-07-27 14:40:30,944 - WARNING - 異常-主軸上方ACM 建議-修整砂輪
2024-07-27 14:40:30,951 - WARNING - 異常-載台CC 建議-修整砂輪
2024-07-27 14:40:53,127 - WARNING - 異常-主軸上方ACM 建議-修整砂輪
2024-07-27 14:40:53,127 - WARNING - 異常-載台CC 建議-修整砂輪
2024-07-27 14:41:01,942 - WARNING - 異常-主軸上方ACM 建議-修整砂輪
2024-07-27 14:41:01,945 - WARNING - 異常-載台CC 建議-修整砂輪
2024-07-27 14:42:15,624 - WARNING - 異常-主軸上方ACM 建議-修整砂輪
2024-07-27 14:42:15,626 - WARNING - 異常-載台CC 建議-修整砂輪
2024-07-27 14:44:58,468 - WARNING - 異常-主軸上方ACM 建議-修整砂輪
2024-07-27 14:44:58,470 - WARNING - 異常-載台CC 建議-修整砂輪
2024-07-27 14:48:54,281 - WARNING - 異常-載台CC 建議-修整砂輪
2024-07-27 14:48:54,283 - WARNING - 異常-主軸上方ACM 建議-修整砂輪
2024-07-27 15:31:20,512 - WARNING - 異常-載台CC 建議-修整砂輪
2024-07-27 15:31:20,512 - WARNING - 異常-主軸上方ACM 建議-修整砂輪
2024-07-27 15:31:30,555 - WARNING - 異常-主軸上方ACM 建議-修整砂輪
2024-07-27 15:31:30,557 - WARNING - 異常-載台CC 建議-修整砂輪
2024-07-27 15:32:03,903 - WARNING - 異常-主軸上方ACM 建議-修整砂輪
2024-07-27 15:32:03,906 - WARNING - 異常-載台CC 建議-修整砂輪
2024-07-27 15:32:11,108 - WARNING - 異常-主軸上方ACM 建議-修整砂輪
2024-07-27 15:32:11,109 - WARNING - 異常-載台CC 建議-修整砂輪
2024-07-27 15:32:17,775 - WARNING - 異常-主軸上方ACM 建議-修整砂輪
2024-07-27 15:32:17,777 - WARNING - 異常-載台CC 建議-修整砂輪
2024-07-27 15:32:33,008 - WARNING - 異常-載台CC 建議-修整砂輪
2024-07-27 15:32:33,008 - WARNING - 異常-主軸上方ACM 建議-修整砂輪
2024-07-27 15:32:49,651 - WARNING - 異常-主軸上方ACM 建議-修整砂輪
2024-07-27 15:32:49,655 - WARNING - 異常-載台CC 建議-修整砂輪
2024-07-27 15:34:01,914 - WARNING - 異常-主軸上方ACM 建議-修整砂輪
2024-07-27 15:34:01,917 - WARNING - 異常-載台CC 建議-修整砂輪
2024-07-27 15:35:37,010 - WARNING - 異常-主軸上方ACM 建議-修整砂輪
2024-07-27 15:35:37,014 - WARNING - 異常-載台CC 建議-修整砂輪
2024-07-27 15:49:40,798 - WARNING - 異常-主軸上方ACM 建議-修整砂輪
2024-07-27 15:49:40,799 - WARNING - 異常-載台CC 建議-修整砂輪
2024-07-27 15:52:16,797 - WARNING - 異常-主軸上方ACM 建議-修整砂輪
2024-07-27 15:52:16,798 - WARNING - 異常-載台CC 建議-修整砂輪
2024-07-27 15:53:15,721 - WARNING - 異常-主軸上方ACM 建議-修整砂輪
2024-07-27 15:53:15,726 - WARNING - 異常-載台CC 建議-修整砂輪
2024-07-27 15:54:49,677 - WARNING - 異常-主軸上方ACM 建議-修整砂輪
2024-07-27 15:54:49,680 - WARNING - 異常-載台CC 建議-修整砂輪
2024-07-27 15:55:41,866 - WARNING - 異常-主軸上方ACM 建議-修整砂輪
2024-07-27 15:55:41,867 - WARNING - 異常-載台CC 建議-修整砂輪
2024-07-27 15:55:49,396 - WARNING - 異常-主軸上方ACM 建議-修整砂輪
2024-07-27 15:55:49,398 - WARNING - 異常-載台CC 建議-修整砂輪
2024-07-27 15:56:04,543 - WARNING - 異常-主軸上方ACM 建議-修整砂輪
2024-07-27 15:56:04,543 - WARNING - 異常-載台CC 建議-修整砂輪
2024-07-27 15:56:27,609 - WARNING - 異常-主軸上方ACM 建議-修整砂輪
2024-07-27 15:56:27,611 - WARNING - 異常-載台CC 建議-修整砂輪
2024-07-27 15:56:41,693 - WARNING - 異常-主軸上方ACM 建議-修整砂輪
2024-07-27 15:56:41,695 - WARNING - 異常-載台CC 建議-修整砂輪
2024-07-27 15:56:50,073 - WARNING - 異常-主軸上方ACM 建議-修整砂輪
2024-07-27 15:56:50,075 - WARNING - 異常-載台CC 建議-修整砂輪
2024-07-27 15:57:09,106 - WARNING - 異常-主軸上方ACM 建議-修整砂輪
2024-07-27 15:57:09,107 - WARNING - 異常-載台CC 建議-修整砂輪
2024-07-27 15:57:24,609 - WARNING - 異常-主軸上方ACM 建議-修整砂輪
2024-07-27 15:57:24,614 - WARNING - 異常-載台CC 建議-修整砂輪
2024-07-27 15:58:44,689 - WARNING - 異常-主軸上方ACM 建議-修整砂輪
2024-07-27 15:58:44,691 - WARNING - 異常-載台CC 建議-修整砂輪
2024-07-27 16:00:12,938 - WARNING - 異常-主軸上方ACM 建議-修整砂輪
2024-07-27 16:00:12,941 - WARNING - 異常-載台CC 建議-修整砂輪
2024-07-27 16:00:51,034 - WARNING - 異常-主軸上方ACM 建議-修整砂輪
2024-07-27 16:00:51,038 - WARNING - 異常-載台CC 建議-修整砂輪
2024-07-27 16:02:42,671 - WARNING - 異常-主軸上方ACM 建議-修整砂輪
2024-07-27 16:02:42,675 - WARNING - 異常-載台CC 建議-修整砂輪
2024-07-27 16:07:05,539 - WARNING - 異常-主軸上方ACM 建議-修整砂輪
2024-07-27 16:07:05,541 - WARNING - 異常-載台CC 建議-修整砂輪
2024-07-27 19:25:33,225 - WARNING - 異常-主軸上方ACM 建議-修整砂輪
2024-07-27 19:25:33,228 - WARNING - 異常-載台CC 建議-修整砂輪
2024-07-27 19:26:04,995 - WARNING - 異常-主軸上方ACM 建議-修整砂輪
2024-07-27 19:26:04,997 - WARNING - 異常-載台CC 建議-修整砂輪
2024-08-12 22:01:47,790 - WARNING - 異常-主軸上方ACM 建議-修整砂輪
2024-08-12 22:02:37,764 - WARNING - 異常-主軸上方ACM 建議-修整砂輪
2024-08-12 22:02:37,767 - WARNING - 異常-載台CC 建議-修整砂輪
2024-08-12 22:05:46,225 - WARNING - 異常-主軸上方ACM 建議-修整砂輪
2024-08-12 22:05:46,227 - WARNING - 異常-載台CC 建議-修整砂輪
2024-08-12 22:06:26,707 - WARNING - 異常-載台CC 建議-修整砂輪
2024-08-12 22:06:26,708 - WARNING - 異常-主軸上方ACM 建議-修整砂輪
2024-08-12 22:55:56,514 - WARNING - 異常-主軸上方ACM 建議-修整砂輪
2024-08-12 22:55:56,517 - WARNING - 異常-載台CC 建議-修整砂輪
2024-08-12 23:10:51,239 - WARNING - 異常-主軸上方ACM 建議-修整砂輪
2024-08-12 23:10:51,241 - WARNING - 異常-載台CC 建議-修整砂輪
2024-08-12 23:11:16,421 - WARNING - 異常-主軸上方ACM 建議-修整砂輪
2024-08-12 23:11:16,423 - WARNING - 異常-載台CC 建議-修整砂輪
2024-08-12 23:12:10,620 - WARNING - 異常-主軸上方ACM 建議-修整砂輪
2024-08-12 23:12:10,626 - WARNING - 異常-載台CC 建議-修整砂輪
2024-08-12 23:12:32,320 - WARNING - 異常-主軸上方ACM 建議-修整砂輪
2024-08-12 23:12:32,323 - WARNING - 異常-載台CC 建議-修整砂輪
2024-08-12 23:14:59,732 - WARNING - 異常-主軸上方ACM 建議-修整砂輪
2024-08-12 23:14:59,733 - WARNING - 異常-載台CC 建議-修整砂輪
2024-08-12 23:14:59,734 - WARNING - 異常-主軸下方ACM 建議-修整砂輪
2024-09-01 14:17:35,845 - ERROR - Error processing MQTT message: 'dict' object has no attribute 'id'
2024-09-01 14:17:43,292 - ERROR - Error processing MQTT message: 'dict' object has no attribute 'id'
2024-09-01 14:17:53,085 - ERROR - Error processing MQTT message: Working outside of application context.

This typically means that you attempted to use functionality that needed
the current application. To solve this, set up an application context
with app.app_context(). See the documentation for more information.
2024-09-01 14:17:54,602 - ERROR - Error processing MQTT message: Working outside of application context.

This typically means that you attempted to use functionality that needed
the current application. To solve this, set up an application context
with app.app_context(). See the documentation for more information.
2024-09-01 14:17:58,867 - ERROR - Error processing MQTT message: Working outside of application context.

This typically means that you attempted to use functionality that needed
the current application. To solve this, set up an application context
with app.app_context(). See the documentation for more information.
2024-09-01 14:18:07,150 - ERROR - Error processing MQTT message: Working outside of application context.

This typically means that you attempted to use functionality that needed
the current application. To solve this, set up an application context
with app.app_context(). See the documentation for more information.
2024-09-01 14:18:56,694 - ERROR - Error processing MQTT message: 'dict' object has no attribute 'id'
2024-09-01 14:18:56,695 - ERROR - Error processing MQTT message: 'dict' object has no attribute 'id'
2024-09-01 14:19:19,834 - ERROR - Error processing MQTT message: 'dict' object has no attribute 'id'
2024-09-01 14:20:27,825 - ERROR - Error processing MQTT message: 'dict' object has no attribute 'id'
2024-09-01 14:20:27,827 - ERROR - Error processing MQTT message: 'dict' object has no attribute 'id'
2024-09-01 14:21:27,073 - ERROR - Error processing MQTT message: 'dict' object has no attribute 'id'
2024-09-01 14:21:54,290 - ERROR - Error processing MQTT message: 'dict' object has no attribute 'id'
2024-09-01 14:21:57,276 - ERROR - Error processing MQTT message: 'dict' object has no attribute 'id'
2024-09-01 14:23:09,300 - ERROR - Error processing MQTT message: Working outside of application context.

This typically means that you attempted to use functionality that needed
the current application. To solve this, set up an application context
with app.app_context(). See the documentation for more information.
2024-09-01 14:23:09,301 - ERROR - Error processing MQTT message: Working outside of application context.

This typically means that you attempted to use functionality that needed
the current application. To solve this, set up an application context
with app.app_context(). See the documentation for more information.
2024-09-01 14:23:11,363 - ERROR - Error processing MQTT message: Working outside of application context.

This typically means that you attempted to use functionality that needed
the current application. To solve this, set up an application context
with app.app_context(). See the documentation for more information.
2024-09-01 14:23:11,363 - ERROR - Error processing MQTT message: Working outside of application context.

This typically means that you attempted to use functionality that needed
the current application. To solve this, set up an application context
with app.app_context(). See the documentation for more information.
2024-09-01 14:23:41,711 - ERROR - Error processing MQTT message: Working outside of application context.

This typically means that you attempted to use functionality that needed
the current application. To solve this, set up an application context
with app.app_context(). See the documentation for more information.
2024-09-01 14:23:43,783 - ERROR - Error processing MQTT message: Working outside of application context.

This typically means that you attempted to use functionality that needed
the current application. To solve this, set up an application context
with app.app_context(). See the documentation for more information.
2024-09-01 14:26:43,666 - ERROR - Error processing MQTT message: Working outside of application context.

This typically means that you attempted to use functionality that needed
the current application. To solve this, set up an application context
with app.app_context(). See the documentation for more information.
2024-09-01 14:26:43,667 - ERROR - Error processing MQTT message: Working outside of application context.

This typically means that you attempted to use functionality that needed
the current application. To solve this, set up an application context
with app.app_context(). See the documentation for more information.
2024-09-01 14:28:22,735 - ERROR - Error processing MQTT message: 'dict' object has no attribute 'id'
2024-09-01 14:28:22,735 - ERROR - Error processing MQTT message: 'dict' object has no attribute 'id'
2024-09-01 14:28:25,108 - ERROR - Error processing MQTT message: 'dict' object has no attribute 'id'
2024-09-01 14:28:25,108 - ERROR - Error processing MQTT message: 'dict' object has no attribute 'id'
2024-09-01 17:17:56,383 - ERROR - Error processing MQTT message: 'Sensors' object is not subscriptable
2024-09-01 17:17:56,403 - ERROR - Error processing MQTT message: 'Sensors' object is not subscriptable
2024-09-01 17:18:25,484 - ERROR - Error processing MQTT message: 'Sensors' object is not subscriptable
2024-09-01 17:18:25,485 - ERROR - Error processing MQTT message: 'Sensors' object is not subscriptable
2024-09-01 17:18:53,777 - ERROR - Error processing MQTT message: 'Sensors' object is not subscriptable
2024-09-01 17:18:53,795 - ERROR - Error processing MQTT message: 'Sensors' object is not subscriptable
2024-09-01 17:19:18,434 - ERROR - Error processing MQTT message: 'Sensors' object is not subscriptable
2024-09-01 17:19:58,407 - ERROR - Error processing MQTT message: '>=' not supported between instances of 'str' and 'float'
2024-09-01 17:29:47,931 - ERROR - Error processing MQTT message: 'dict' object has no attribute 'id'
2024-09-01 17:29:47,931 - ERROR - Error processing MQTT message: 'dict' object has no attribute 'id'
2024-09-10 12:51:01,057 - ERROR - Error processing MQTT message: Working outside of request context.

This typically means that you attempted to use functionality that needed
an active HTTP request. Consult the documentation on testing for
information about how to avoid this problem.
2024-09-10 12:51:01,057 - ERROR - Error processing MQTT message: Working outside of request context.

This typically means that you attempted to use functionality that needed
an active HTTP request. Consult the documentation on testing for
information about how to avoid this problem.
2024-09-10 12:52:11,353 - ERROR - Error processing MQTT message: Working outside of request context.

This typically means that you attempted to use functionality that needed
an active HTTP request. Consult the documentation on testing for
information about how to avoid this problem.
2024-09-10 12:52:14,758 - ERROR - Error processing MQTT message: Working outside of request context.

This typically means that you attempted to use functionality that needed
an active HTTP request. Consult the documentation on testing for
information about how to avoid this problem.
2024-09-10 12:52:17,277 - ERROR - Error processing MQTT message: Working outside of request context.

This typically means that you attempted to use functionality that needed
an active HTTP request. Consult the documentation on testing for
information about how to avoid this problem.
2024-09-10 12:52:25,041 - ERROR - Error processing MQTT message: Working outside of request context.

This typically means that you attempted to use functionality that needed
an active HTTP request. Consult the documentation on testing for
information about how to avoid this problem.
2024-09-10 12:53:27,824 - WARNING - 異常-主軸上方1 建議-修整砂輪
2024-09-10 12:53:28,632 - WARNING - 異常-主軸上方1 建議-修整砂輪
2024-09-10 12:53:41,835 - WARNING - 異常-主軸上方1 建議-修整砂輪
2024-09-10 12:53:42,357 - WARNING - 異常-主軸上方1 建議-修整砂輪
2024-09-10 12:54:26,541 - ERROR - Error processing MQTT message: Working outside of request context.

This typically means that you attempted to use functionality that needed
an active HTTP request. Consult the documentation on testing for
information about how to avoid this problem.
2024-09-10 12:54:26,541 - ERROR - Error processing MQTT message: Working outside of request context.

This typically means that you attempted to use functionality that needed
an active HTTP request. Consult the documentation on testing for
information about how to avoid this problem.
2024-09-10 16:37:20,646 - WARNING - 異常-主軸上方1 建議-修整砂輪
2024-09-10 16:37:21,043 - WARNING - 異常-主軸上方1 建議-修整砂輪
2024-09-10 16:37:26,367 - WARNING - 異常-主軸上方1 建議-修整砂輪
2024-09-10 16:37:26,818 - WARNING - 異常-主軸上方1 建議-修整砂輪
2024-09-10 16:38:18,172 - WARNING - 異常-主軸上方1 建議-修整砂輪
2024-09-10 16:38:24,154 - WARNING - 異常-主軸上方1 建議-修整砂輪
2024-09-10 16:38:27,932 - WARNING - 異常-主軸上方1 建議-修整砂輪
2024-09-10 16:38:29,431 - WARNING - 異常-主軸上方1 建議-修整砂輪
2024-09-10 16:38:30,936 - WARNING - 異常-主軸上方1 建議-修整砂輪
2024-09-10 16:38:32,447 - WARNING - 異常-主軸上方1 建議-修整砂輪
2024-09-10 16:38:38,150 - WARNING - 異常-主軸上方1 建議-修整砂輪
2024-09-10 16:39:10,480 - WARNING - 異常-主軸上方1 建議-修整砂輪
2024-09-10 16:39:10,511 - WARNING - 異常-主軸上方1 建議-修整砂輪
2024-09-10 16:39:13,646 - WARNING - 異常-主軸上方1 建議-修整砂輪
2024-09-10 16:39:13,650 - WARNING - 異常-主軸上方1 建議-修整砂輪
2024-09-10 16:39:15,851 - WARNING - 異常-主軸上方1 建議-修整砂輪
2024-09-10 16:39:15,854 - WARNING - 異常-主軸上方1 建議-修整砂輪
2024-09-10 17:12:05,174 - WARNING - 異常-主軸上方1 建議-修整砂輪
2024-09-10 17:12:05,193 - WARNING - 異常-主軸上方1 建議-修整砂輪
2024-09-10 17:19:00,545 - WARNING - 異常-主軸上方1 建議-修整砂輪
2024-09-10 17:19:00,551 - WARNING - 異常-主軸上方1 建議-修整砂輪
2024-09-10 17:19:24,550 - WARNING - 異常-主軸上方1 建議-修整砂輪
2024-09-10 17:19:24,557 - WARNING - 異常-主軸上方1 建議-修整砂輪
2024-09-10 17:19:27,654 - WARNING - 異常-主軸上方1 建議-修整砂輪
2024-09-10 17:19:27,657 - WARNING - 異常-主軸上方1 建議-修整砂輪
2024-09-10 17:19:29,657 - WARNING - 異常-主軸上方1 建議-修整砂輪
2024-09-10 17:19:29,659 - WARNING - 異常-主軸上方1 建議-修整砂輪
2024-09-10 17:19:34,432 - WARNING - 異常-主軸上方1 建議-修整砂輪
2024-09-10 17:19:34,435 - WARNING - 異常-主軸上方1 建議-修整砂輪
2024-09-10 17:20:48,979 - WARNING - 異常-主軸上方1 建議-修整砂輪
2024-09-10 17:20:48,996 - WARNING - 異常-主軸上方1 建議-修整砂輪
2024-09-10 17:20:51,652 - WARNING - 異常-主軸上方1 建議-修整砂輪
2024-09-10 17:20:51,657 - WARNING - 異常-主軸上方1 建議-修整砂輪
2024-09-10 17:21:50,849 - WARNING - 異常-主軸上方1 建議-修整砂輪
2024-09-10 17:21:50,856 - WARNING - 異常-主軸上方1 建議-修整砂輪
2024-09-10 17:22:14,004 - WARNING - 異常-主軸上方1 建議-修整砂輪
2024-09-10 17:22:14,035 - WARNING - 異常-主軸上方1 建議-修整砂輪
2024-09-10 17:27:54,084 - WARNING - 異常-主軸上方1 建議-修整砂輪
2024-09-10 17:27:54,087 - WARNING - 異常-主軸上方1 建議-修整砂輪
2024-09-10 17:27:57,155 - WARNING - 異常-主軸上方1 建議-修整砂輪
2024-09-10 17:27:57,158 - WARNING - 異常-主軸上方1 建議-修整砂輪
2024-09-10 17:27:58,950 - WARNING - 異常-主軸上方1 建議-修整砂輪
2024-09-10 17:27:58,953 - WARNING - 異常-主軸上方1 建議-修整砂輪
2024-09-10 17:28:00,675 - WARNING - 異常-主軸上方1 建議-修整砂輪
2024-09-10 17:28:00,683 - WARNING - 異常-主軸上方1 建議-修整砂輪
2024-09-10 17:29:08,652 - WARNING - 異常-主軸上方1 建議-修整砂輪
2024-09-10 17:30:23,087 - WARNING - 異常-主軸上方1 建議-修整砂輪
2024-09-10 17:30:24,626 - WARNING - 異常-主軸上方1 建議-修整砂輪
2024-09-10 17:31:21,063 - WARNING - 異常-主軸上方1 建議-修整砂輪
2024-09-10 17:31:22,642 - WARNING - 異常-主軸上方1 建議-修整砂輪
2024-09-10 17:31:24,609 - WARNING - 異常-主軸上方1 建議-修整砂輪
2024-09-10 17:31:49,777 - WARNING - 異常-主軸上方1 建議-修整砂輪
2024-09-10 17:31:51,652 - WARNING - 異常-主軸上方1 建議-修整砂輪
2024-09-10 17:31:53,088 - WARNING - 異常-主軸上方1 建議-修整砂輪
2024-09-10 17:31:54,559 - WARNING - 異常-主軸上方1 建議-修整砂輪
2024-09-10 17:31:56,058 - WARNING - 異常-主軸上方1 建議-修整砂輪
2024-09-10 17:31:57,131 - WARNING - 異常-主軸上方1 建議-修整砂輪
2024-09-10 17:31:58,654 - WARNING - 異常-主軸上方1 建議-修整砂輪
2024-09-10 17:32:00,132 - WARNING - 異常-主軸上方1 建議-修整砂輪
2024-09-10 17:32:19,414 - WARNING - 異常-主軸上方1 建議-修整砂輪
2024-09-10 17:32:19,430 - WARNING - 異常-主軸上方1 建議-修整砂輪
2024-09-10 17:32:21,145 - WARNING - 異常-主軸上方1 建議-修整砂輪
2024-09-10 17:32:21,147 - WARNING - 異常-主軸上方1 建議-修整砂輪
2024-09-10 17:32:22,991 - WARNING - 異常-主軸上方1 建議-修整砂輪
2024-09-10 17:32:22,992 - WARNING - 異常-主軸上方1 建議-修整砂輪
2024-09-10 17:32:24,460 - WARNING - 異常-主軸上方1 建議-修整砂輪
2024-09-10 17:32:24,461 - WARNING - 異常-主軸上方1 建議-修整砂輪
2024-09-10 17:32:25,605 - WARNING - 異常-主軸上方1 建議-修整砂輪
2024-09-10 17:32:25,606 - WARNING - 異常-主軸上方1 建議-修整砂輪
2024-09-10 17:32:28,762 - WARNING - 異常-主軸上方1 建議-修整砂輪
2024-09-10 17:32:28,846 - WARNING - 異常-主軸上方1 建議-修整砂輪
2024-09-10 17:32:30,481 - WARNING - 異常-主軸上方1 建議-修整砂輪
2024-09-10 17:32:30,482 - WARNING - 異常-主軸上方1 建議-修整砂輪
2024-09-10 17:34:09,473 - WARNING - 異常-主軸上方1 建議-修整砂輪
2024-09-10 17:34:09,530 - WARNING - 異常-主軸上方1 建議-修整砂輪
2024-09-10 17:34:11,016 - WARNING - 異常-主軸上方1 建議-修整砂輪
2024-09-10 17:34:11,017 - WARNING - 異常-主軸上方1 建議-修整砂輪
2024-09-10 17:34:12,479 - WARNING - 異常-主軸上方1 建議-修整砂輪
2024-09-10 17:34:12,480 - WARNING - 異常-主軸上方1 建議-修整砂輪
2024-09-10 17:34:17,026 - WARNING - 異常-主軸上方1 建議-修整砂輪
2024-09-10 17:34:17,028 - WARNING - 異常-主軸上方1 建議-修整砂輪
2024-09-10 17:34:18,504 - WARNING - 異常-主軸上方1 建議-修整砂輪
2024-09-10 17:34:18,508 - WARNING - 異常-主軸上方1 建議-修整砂輪
2024-09-10 17:34:28,993 - WARNING - 異常-主軸上方1 建議-修整砂輪
2024-09-10 17:34:30,670 - WARNING - 異常-主軸上方1 建議-修整砂輪
2024-09-10 17:34:32,153 - WARNING - 異常-主軸上方1 建議-修整砂輪
2024-09-10 17:34:33,645 - WARNING - 異常-主軸上方1 建議-修整砂輪
2024-09-10 17:34:35,125 - WARNING - 異常-主軸上方1 建議-修整砂輪
2024-09-10 17:35:24,483 - WARNING - 異常-主軸上方1 建議-修整砂輪
2024-09-10 17:35:24,514 - WARNING - 異常-主軸上方1 建議-修整砂輪
2024-09-10 17:42:56,045 - WARNING - 異常-主軸上方1 建議-修整砂輪
2024-09-10 17:42:58,192 - WARNING - 異常-主軸上方1 建議-修整砂輪
2024-09-10 17:42:59,676 - WARNING - 異常-主軸上方1 建議-修整砂輪
2024-09-10 17:43:00,878 - WARNING - 異常-主軸上方1 建議-修整砂輪
2024-09-10 17:53:42,195 - WARNING - 異常-主軸上方1 建議-修整砂輪
2024-09-10 17:53:42,197 - WARNING - 異常-主軸上方1 建議-修整砂輪
2024-09-10 17:53:44,659 - WARNING - 異常-主軸上方1 建議-修整砂輪
2024-09-10 17:53:44,660 - WARNING - 異常-主軸上方1 建議-修整砂輪
2024-09-10 17:53:45,991 - WARNING - 異常-主軸上方1 建議-修整砂輪
2024-09-10 17:53:46,008 - WARNING - 異常-主軸上方1 建議-修整砂輪
2024-09-10 17:53:49,117 - WARNING - 異常-主軸上方1 建議-修整砂輪
2024-09-10 17:53:49,120 - WARNING - 異常-主軸上方1 建議-修整砂輪
2024-09-10 17:53:50,611 - WARNING - 異常-主軸上方1 建議-修整砂輪
2024-09-10 17:53:50,613 - WARNING - 異常-主軸上方1 建議-修整砂輪
2024-09-10 17:53:52,151 - WARNING - 異常-主軸上方1 建議-修整砂輪
2024-09-10 17:53:52,152 - WARNING - 異常-主軸上方1 建議-修整砂輪
2024-09-10 17:54:32,155 - WARNING - 異常-主軸上方1 建議-修整砂輪
2024-09-10 17:54:36,167 - WARNING - 異常-主軸上方1 建議-修整砂輪
2024-09-10 17:54:37,673 - WARNING - 異常-主軸上方1 建議-修整砂輪
2024-09-10 17:54:39,103 - WARNING - 異常-主軸上方1 建議-修整砂輪
2024-09-10 17:54:40,626 - WARNING - 異常-主軸上方1 建議-修整砂輪
2024-09-10 17:54:42,122 - WARNING - 異常-主軸上方1 建議-修整砂輪
2024-09-10 17:54:43,617 - WARNING - 異常-主軸上方1 建議-修整砂輪
2024-09-10 17:54:45,147 - WARNING - 異常-主軸上方1 建議-修整砂輪
2024-09-10 17:54:48,170 - WARNING - 異常-主軸上方1 建議-修整砂輪
2024-09-10 17:54:50,176 - WARNING - 異常-主軸上方1 建議-修整砂輪
2024-09-10 17:54:51,653 - WARNING - 異常-主軸上方1 建議-修整砂輪
2024-09-10 17:54:52,950 - WARNING - 異常-主軸上方1 建議-修整砂輪
2024-09-10 17:54:58,026 - WARNING - 異常-主軸上方1 建議-修整砂輪
2024-09-10 17:54:59,499 - WARNING - 異常-主軸上方1 建議-修整砂輪
2024-09-10 17:55:29,165 - WARNING - 異常-主軸上方1 建議-修整砂輪
2024-09-10 17:55:30,173 - WARNING - 異常-主軸上方1 建議-修整砂輪
2024-09-10 17:55:31,717 - WARNING - 異常-主軸上方1 建議-修整砂輪
2024-09-10 17:55:33,176 - WARNING - 異常-主軸上方1 建議-修整砂輪
2024-09-10 17:55:34,183 - WARNING - 異常-主軸上方1 建議-修整砂輪
2024-09-10 17:55:42,681 - WARNING - 異常-主軸上方1 建議-修整砂輪
2024-09-10 17:55:43,991 - WARNING - 異常-主軸上方1 建議-修整砂輪
2024-09-10 17:55:45,482 - WARNING - 異常-主軸上方1 建議-修整砂輪
2024-09-10 17:55:47,019 - WARNING - 異常-主軸上方1 建議-修整砂輪
2024-09-10 17:57:13,157 - WARNING - 異常-主軸上方1 建議-修整砂輪
2024-09-10 17:57:16,155 - WARNING - 異常-主軸上方1 建議-修整砂輪
2024-09-10 17:57:17,669 - WARNING - 異常-主軸上方1 建議-修整砂輪
2024-09-10 17:57:18,877 - WARNING - 異常-主軸上方1 建議-修整砂輪
2024-10-24 16:31:17,331 - WARNING - 異常-00ACM 建議-00
2024-10-24 16:31:18,343 - WARNING - 異常-00ACM 建議-00
2024-10-24 16:32:04,842 - WARNING - 異常-00ACM 建議-00
2024-10-24 18:49:48,343 - WARNING - 異常-00ACM 建議-00
2024-10-24 18:49:51,242 - WARNING - 異常-00ACM 建議-00
2024-10-25 09:14:30,905 - ERROR - Exception on / [POST]
Traceback (most recent call last):
  File "/usr/local/lib/python3.9/site-packages/flask/app.py", line 1473, in wsgi_app
    response = self.full_dispatch_request()
  File "/usr/local/lib/python3.9/site-packages/flask/app.py", line 882, in full_dispatch_request
    rv = self.handle_user_exception(e)
  File "/usr/local/lib/python3.9/site-packages/flask/app.py", line 880, in full_dispatch_request
    rv = self.dispatch_request()
  File "/usr/local/lib/python3.9/site-packages/flask/app.py", line 865, in dispatch_request
    return self.ensure_sync(self.view_functions[rule.endpoint])(**view_args)  # type: ignore[no-any-return]
  File "/flask/app/main/routes.py", line 12, in index
    form_login()
  File "/flask/app/main/code.py", line 14, in form_login
    user = db.session.query(User).filter_by(email=email).first()
  File "/usr/local/lib/python3.9/site-packages/sqlalchemy/orm/query.py", line 2728, in first
    return self.limit(1)._iter().first()  # type: ignore
  File "/usr/local/lib/python3.9/site-packages/sqlalchemy/orm/query.py", line 2827, in _iter
    result: Union[ScalarResult[_T], Result[_T]] = self.session.execute(
  File "/usr/local/lib/python3.9/site-packages/sqlalchemy/orm/session.py", line 2362, in execute
    return self._execute_internal(
  File "/usr/local/lib/python3.9/site-packages/sqlalchemy/orm/session.py", line 2237, in _execute_internal
    conn = self._connection_for_bind(bind)
  File "/usr/local/lib/python3.9/site-packages/sqlalchemy/orm/session.py", line 2106, in _connection_for_bind
    return trans._connection_for_bind(engine, execution_options)
  File "<string>", line 2, in _connection_for_bind
  File "/usr/local/lib/python3.9/site-packages/sqlalchemy/orm/state_changes.py", line 139, in _go
    ret_value = fn(self, *arg, **kw)
  File "/usr/local/lib/python3.9/site-packages/sqlalchemy/orm/session.py", line 1189, in _connection_for_bind
    conn = bind.connect()
  File "/usr/local/lib/python3.9/site-packages/sqlalchemy/engine/base.py", line 3278, in connect
    return self._connection_cls(self)
  File "/usr/local/lib/python3.9/site-packages/sqlalchemy/engine/base.py", line 146, in __init__
    self._dbapi_connection = engine.raw_connection()
  File "/usr/local/lib/python3.9/site-packages/sqlalchemy/engine/base.py", line 3302, in raw_connection
    return self.pool.connect()
  File "/usr/local/lib/python3.9/site-packages/sqlalchemy/pool/base.py", line 449, in connect
    return _ConnectionFairy._checkout(self)
  File "/usr/local/lib/python3.9/site-packages/sqlalchemy/pool/base.py", line 1263, in _checkout
    fairy = _ConnectionRecord.checkout(pool)
  File "/usr/local/lib/python3.9/site-packages/sqlalchemy/pool/base.py", line 712, in checkout
    rec = pool._do_get()
  File "/usr/local/lib/python3.9/site-packages/sqlalchemy/pool/impl.py", line 180, in _do_get
    self._dec_overflow()
  File "/usr/local/lib/python3.9/site-packages/sqlalchemy/util/langhelpers.py", line 146, in __exit__
    raise exc_value.with_traceback(exc_tb)
  File "/usr/local/lib/python3.9/site-packages/sqlalchemy/pool/impl.py", line 177, in _do_get
    return self._create_connection()
  File "/usr/local/lib/python3.9/site-packages/sqlalchemy/pool/base.py", line 390, in _create_connection
    return _ConnectionRecord(self)
  File "/usr/local/lib/python3.9/site-packages/sqlalchemy/pool/base.py", line 674, in __init__
    self.__connect()
  File "/usr/local/lib/python3.9/site-packages/sqlalchemy/pool/base.py", line 901, in __connect
    pool.logger.debug("Error on connect(): %s", e)
  File "/usr/local/lib/python3.9/site-packages/sqlalchemy/util/langhelpers.py", line 146, in __exit__
    raise exc_value.with_traceback(exc_tb)
  File "/usr/local/lib/python3.9/site-packages/sqlalchemy/pool/base.py", line 896, in __connect
    self.dbapi_connection = connection = pool._invoke_creator(self)
  File "/usr/local/lib/python3.9/site-packages/sqlalchemy/engine/create.py", line 643, in connect
    return dialect.connect(*cargs, **cparams)
  File "/usr/local/lib/python3.9/site-packages/sqlalchemy/engine/default.py", line 621, in connect
    return self.loaded_dbapi.connect(*cargs, **cparams)
  File "/usr/local/lib/python3.9/site-packages/pymysql/connections.py", line 361, in __init__
    self.connect()
  File "/usr/local/lib/python3.9/site-packages/pymysql/connections.py", line 669, in connect
    self._request_authentication()
  File "/usr/local/lib/python3.9/site-packages/pymysql/connections.py", line 979, in _request_authentication
    auth_packet = _auth.caching_sha2_password_auth(self, auth_packet)
  File "/usr/local/lib/python3.9/site-packages/pymysql/_auth.py", line 267, in caching_sha2_password_auth
    data = sha2_rsa_encrypt(conn.password, conn.salt, conn.server_public_key)
  File "/usr/local/lib/python3.9/site-packages/pymysql/_auth.py", line 144, in sha2_rsa_encrypt
    raise RuntimeError(
RuntimeError: 'cryptography' package is required for sha256_password or caching_sha2_password auth methods
2024-10-25 09:14:49,001 - ERROR - Exception on / [POST]
Traceback (most recent call last):
  File "/usr/local/lib/python3.9/site-packages/flask/app.py", line 1473, in wsgi_app
    response = self.full_dispatch_request()
  File "/usr/local/lib/python3.9/site-packages/flask/app.py", line 882, in full_dispatch_request
    rv = self.handle_user_exception(e)
  File "/usr/local/lib/python3.9/site-packages/flask/app.py", line 880, in full_dispatch_request
    rv = self.dispatch_request()
  File "/usr/local/lib/python3.9/site-packages/flask/app.py", line 865, in dispatch_request
    return self.ensure_sync(self.view_functions[rule.endpoint])(**view_args)  # type: ignore[no-any-return]
  File "/flask/app/main/routes.py", line 12, in index
    form_login()
  File "/flask/app/main/code.py", line 14, in form_login
    user = db.session.query(User).filter_by(email=email).first()
  File "/usr/local/lib/python3.9/site-packages/sqlalchemy/orm/query.py", line 2728, in first
    return self.limit(1)._iter().first()  # type: ignore
  File "/usr/local/lib/python3.9/site-packages/sqlalchemy/orm/query.py", line 2827, in _iter
    result: Union[ScalarResult[_T], Result[_T]] = self.session.execute(
  File "/usr/local/lib/python3.9/site-packages/sqlalchemy/orm/session.py", line 2362, in execute
    return self._execute_internal(
  File "/usr/local/lib/python3.9/site-packages/sqlalchemy/orm/session.py", line 2237, in _execute_internal
    conn = self._connection_for_bind(bind)
  File "/usr/local/lib/python3.9/site-packages/sqlalchemy/orm/session.py", line 2106, in _connection_for_bind
    return trans._connection_for_bind(engine, execution_options)
  File "<string>", line 2, in _connection_for_bind
  File "/usr/local/lib/python3.9/site-packages/sqlalchemy/orm/state_changes.py", line 139, in _go
    ret_value = fn(self, *arg, **kw)
  File "/usr/local/lib/python3.9/site-packages/sqlalchemy/orm/session.py", line 1189, in _connection_for_bind
    conn = bind.connect()
  File "/usr/local/lib/python3.9/site-packages/sqlalchemy/engine/base.py", line 3278, in connect
    return self._connection_cls(self)
  File "/usr/local/lib/python3.9/site-packages/sqlalchemy/engine/base.py", line 146, in __init__
    self._dbapi_connection = engine.raw_connection()
  File "/usr/local/lib/python3.9/site-packages/sqlalchemy/engine/base.py", line 3302, in raw_connection
    return self.pool.connect()
  File "/usr/local/lib/python3.9/site-packages/sqlalchemy/pool/base.py", line 449, in connect
    return _ConnectionFairy._checkout(self)
  File "/usr/local/lib/python3.9/site-packages/sqlalchemy/pool/base.py", line 1263, in _checkout
    fairy = _ConnectionRecord.checkout(pool)
  File "/usr/local/lib/python3.9/site-packages/sqlalchemy/pool/base.py", line 712, in checkout
    rec = pool._do_get()
  File "/usr/local/lib/python3.9/site-packages/sqlalchemy/pool/impl.py", line 180, in _do_get
    self._dec_overflow()
  File "/usr/local/lib/python3.9/site-packages/sqlalchemy/util/langhelpers.py", line 146, in __exit__
    raise exc_value.with_traceback(exc_tb)
  File "/usr/local/lib/python3.9/site-packages/sqlalchemy/pool/impl.py", line 177, in _do_get
    return self._create_connection()
  File "/usr/local/lib/python3.9/site-packages/sqlalchemy/pool/base.py", line 390, in _create_connection
    return _ConnectionRecord(self)
  File "/usr/local/lib/python3.9/site-packages/sqlalchemy/pool/base.py", line 674, in __init__
    self.__connect()
  File "/usr/local/lib/python3.9/site-packages/sqlalchemy/pool/base.py", line 901, in __connect
    pool.logger.debug("Error on connect(): %s", e)
  File "/usr/local/lib/python3.9/site-packages/sqlalchemy/util/langhelpers.py", line 146, in __exit__
    raise exc_value.with_traceback(exc_tb)
  File "/usr/local/lib/python3.9/site-packages/sqlalchemy/pool/base.py", line 896, in __connect
    self.dbapi_connection = connection = pool._invoke_creator(self)
  File "/usr/local/lib/python3.9/site-packages/sqlalchemy/engine/create.py", line 643, in connect
    return dialect.connect(*cargs, **cparams)
  File "/usr/local/lib/python3.9/site-packages/sqlalchemy/engine/default.py", line 621, in connect
    return self.loaded_dbapi.connect(*cargs, **cparams)
  File "/usr/local/lib/python3.9/site-packages/pymysql/connections.py", line 361, in __init__
    self.connect()
  File "/usr/local/lib/python3.9/site-packages/pymysql/connections.py", line 669, in connect
    self._request_authentication()
  File "/usr/local/lib/python3.9/site-packages/pymysql/connections.py", line 979, in _request_authentication
    auth_packet = _auth.caching_sha2_password_auth(self, auth_packet)
  File "/usr/local/lib/python3.9/site-packages/pymysql/_auth.py", line 267, in caching_sha2_password_auth
    data = sha2_rsa_encrypt(conn.password, conn.salt, conn.server_public_key)
  File "/usr/local/lib/python3.9/site-packages/pymysql/_auth.py", line 144, in sha2_rsa_encrypt
    raise RuntimeError(
RuntimeError: 'cryptography' package is required for sha256_password or caching_sha2_password auth methods
2024-10-25 09:15:06,218 - ERROR - Exception on / [POST]
Traceback (most recent call last):
  File "/usr/local/lib/python3.9/site-packages/flask/app.py", line 1473, in wsgi_app
    response = self.full_dispatch_request()
  File "/usr/local/lib/python3.9/site-packages/flask/app.py", line 882, in full_dispatch_request
    rv = self.handle_user_exception(e)
  File "/usr/local/lib/python3.9/site-packages/flask/app.py", line 880, in full_dispatch_request
    rv = self.dispatch_request()
  File "/usr/local/lib/python3.9/site-packages/flask/app.py", line 865, in dispatch_request
    return self.ensure_sync(self.view_functions[rule.endpoint])(**view_args)  # type: ignore[no-any-return]
  File "/flask/app/main/routes.py", line 12, in index
    form_login()
  File "/flask/app/main/code.py", line 14, in form_login
    user = db.session.query(User).filter_by(email=email).first()
  File "/usr/local/lib/python3.9/site-packages/sqlalchemy/orm/query.py", line 2728, in first
    return self.limit(1)._iter().first()  # type: ignore
  File "/usr/local/lib/python3.9/site-packages/sqlalchemy/orm/query.py", line 2827, in _iter
    result: Union[ScalarResult[_T], Result[_T]] = self.session.execute(
  File "/usr/local/lib/python3.9/site-packages/sqlalchemy/orm/session.py", line 2362, in execute
    return self._execute_internal(
  File "/usr/local/lib/python3.9/site-packages/sqlalchemy/orm/session.py", line 2237, in _execute_internal
    conn = self._connection_for_bind(bind)
  File "/usr/local/lib/python3.9/site-packages/sqlalchemy/orm/session.py", line 2106, in _connection_for_bind
    return trans._connection_for_bind(engine, execution_options)
  File "<string>", line 2, in _connection_for_bind
  File "/usr/local/lib/python3.9/site-packages/sqlalchemy/orm/state_changes.py", line 139, in _go
    ret_value = fn(self, *arg, **kw)
  File "/usr/local/lib/python3.9/site-packages/sqlalchemy/orm/session.py", line 1189, in _connection_for_bind
    conn = bind.connect()
  File "/usr/local/lib/python3.9/site-packages/sqlalchemy/engine/base.py", line 3278, in connect
    return self._connection_cls(self)
  File "/usr/local/lib/python3.9/site-packages/sqlalchemy/engine/base.py", line 146, in __init__
    self._dbapi_connection = engine.raw_connection()
  File "/usr/local/lib/python3.9/site-packages/sqlalchemy/engine/base.py", line 3302, in raw_connection
    return self.pool.connect()
  File "/usr/local/lib/python3.9/site-packages/sqlalchemy/pool/base.py", line 449, in connect
    return _ConnectionFairy._checkout(self)
  File "/usr/local/lib/python3.9/site-packages/sqlalchemy/pool/base.py", line 1263, in _checkout
    fairy = _ConnectionRecord.checkout(pool)
  File "/usr/local/lib/python3.9/site-packages/sqlalchemy/pool/base.py", line 712, in checkout
    rec = pool._do_get()
  File "/usr/local/lib/python3.9/site-packages/sqlalchemy/pool/impl.py", line 180, in _do_get
    self._dec_overflow()
  File "/usr/local/lib/python3.9/site-packages/sqlalchemy/util/langhelpers.py", line 146, in __exit__
    raise exc_value.with_traceback(exc_tb)
  File "/usr/local/lib/python3.9/site-packages/sqlalchemy/pool/impl.py", line 177, in _do_get
    return self._create_connection()
  File "/usr/local/lib/python3.9/site-packages/sqlalchemy/pool/base.py", line 390, in _create_connection
    return _ConnectionRecord(self)
  File "/usr/local/lib/python3.9/site-packages/sqlalchemy/pool/base.py", line 674, in __init__
    self.__connect()
  File "/usr/local/lib/python3.9/site-packages/sqlalchemy/pool/base.py", line 901, in __connect
    pool.logger.debug("Error on connect(): %s", e)
  File "/usr/local/lib/python3.9/site-packages/sqlalchemy/util/langhelpers.py", line 146, in __exit__
    raise exc_value.with_traceback(exc_tb)
  File "/usr/local/lib/python3.9/site-packages/sqlalchemy/pool/base.py", line 896, in __connect
    self.dbapi_connection = connection = pool._invoke_creator(self)
  File "/usr/local/lib/python3.9/site-packages/sqlalchemy/engine/create.py", line 643, in connect
    return dialect.connect(*cargs, **cparams)
  File "/usr/local/lib/python3.9/site-packages/sqlalchemy/engine/default.py", line 621, in connect
    return self.loaded_dbapi.connect(*cargs, **cparams)
  File "/usr/local/lib/python3.9/site-packages/pymysql/connections.py", line 361, in __init__
    self.connect()
  File "/usr/local/lib/python3.9/site-packages/pymysql/connections.py", line 669, in connect
    self._request_authentication()
  File "/usr/local/lib/python3.9/site-packages/pymysql/connections.py", line 979, in _request_authentication
    auth_packet = _auth.caching_sha2_password_auth(self, auth_packet)
  File "/usr/local/lib/python3.9/site-packages/pymysql/_auth.py", line 267, in caching_sha2_password_auth
    data = sha2_rsa_encrypt(conn.password, conn.salt, conn.server_public_key)
  File "/usr/local/lib/python3.9/site-packages/pymysql/_auth.py", line 144, in sha2_rsa_encrypt
    raise RuntimeError(
RuntimeError: 'cryptography' package is required for sha256_password or caching_sha2_password auth methods
2024-10-25 09:15:11,712 - ERROR - Exception on / [POST]
Traceback (most recent call last):
  File "/usr/local/lib/python3.9/site-packages/flask/app.py", line 1473, in wsgi_app
    response = self.full_dispatch_request()
  File "/usr/local/lib/python3.9/site-packages/flask/app.py", line 882, in full_dispatch_request
    rv = self.handle_user_exception(e)
  File "/usr/local/lib/python3.9/site-packages/flask/app.py", line 880, in full_dispatch_request
    rv = self.dispatch_request()
  File "/usr/local/lib/python3.9/site-packages/flask/app.py", line 865, in dispatch_request
    return self.ensure_sync(self.view_functions[rule.endpoint])(**view_args)  # type: ignore[no-any-return]
  File "/flask/app/main/routes.py", line 12, in index
    form_login()
  File "/flask/app/main/code.py", line 14, in form_login
    user = db.session.query(User).filter_by(email=email).first()
  File "/usr/local/lib/python3.9/site-packages/sqlalchemy/orm/query.py", line 2728, in first
    return self.limit(1)._iter().first()  # type: ignore
  File "/usr/local/lib/python3.9/site-packages/sqlalchemy/orm/query.py", line 2827, in _iter
    result: Union[ScalarResult[_T], Result[_T]] = self.session.execute(
  File "/usr/local/lib/python3.9/site-packages/sqlalchemy/orm/session.py", line 2362, in execute
    return self._execute_internal(
  File "/usr/local/lib/python3.9/site-packages/sqlalchemy/orm/session.py", line 2237, in _execute_internal
    conn = self._connection_for_bind(bind)
  File "/usr/local/lib/python3.9/site-packages/sqlalchemy/orm/session.py", line 2106, in _connection_for_bind
    return trans._connection_for_bind(engine, execution_options)
  File "<string>", line 2, in _connection_for_bind
  File "/usr/local/lib/python3.9/site-packages/sqlalchemy/orm/state_changes.py", line 139, in _go
    ret_value = fn(self, *arg, **kw)
  File "/usr/local/lib/python3.9/site-packages/sqlalchemy/orm/session.py", line 1189, in _connection_for_bind
    conn = bind.connect()
  File "/usr/local/lib/python3.9/site-packages/sqlalchemy/engine/base.py", line 3278, in connect
    return self._connection_cls(self)
  File "/usr/local/lib/python3.9/site-packages/sqlalchemy/engine/base.py", line 146, in __init__
    self._dbapi_connection = engine.raw_connection()
  File "/usr/local/lib/python3.9/site-packages/sqlalchemy/engine/base.py", line 3302, in raw_connection
    return self.pool.connect()
  File "/usr/local/lib/python3.9/site-packages/sqlalchemy/pool/base.py", line 449, in connect
    return _ConnectionFairy._checkout(self)
  File "/usr/local/lib/python3.9/site-packages/sqlalchemy/pool/base.py", line 1263, in _checkout
    fairy = _ConnectionRecord.checkout(pool)
  File "/usr/local/lib/python3.9/site-packages/sqlalchemy/pool/base.py", line 712, in checkout
    rec = pool._do_get()
  File "/usr/local/lib/python3.9/site-packages/sqlalchemy/pool/impl.py", line 180, in _do_get
    self._dec_overflow()
  File "/usr/local/lib/python3.9/site-packages/sqlalchemy/util/langhelpers.py", line 146, in __exit__
    raise exc_value.with_traceback(exc_tb)
  File "/usr/local/lib/python3.9/site-packages/sqlalchemy/pool/impl.py", line 177, in _do_get
    return self._create_connection()
  File "/usr/local/lib/python3.9/site-packages/sqlalchemy/pool/base.py", line 390, in _create_connection
    return _ConnectionRecord(self)
  File "/usr/local/lib/python3.9/site-packages/sqlalchemy/pool/base.py", line 674, in __init__
    self.__connect()
  File "/usr/local/lib/python3.9/site-packages/sqlalchemy/pool/base.py", line 901, in __connect
    pool.logger.debug("Error on connect(): %s", e)
  File "/usr/local/lib/python3.9/site-packages/sqlalchemy/util/langhelpers.py", line 146, in __exit__
    raise exc_value.with_traceback(exc_tb)
  File "/usr/local/lib/python3.9/site-packages/sqlalchemy/pool/base.py", line 896, in __connect
    self.dbapi_connection = connection = pool._invoke_creator(self)
  File "/usr/local/lib/python3.9/site-packages/sqlalchemy/engine/create.py", line 643, in connect
    return dialect.connect(*cargs, **cparams)
  File "/usr/local/lib/python3.9/site-packages/sqlalchemy/engine/default.py", line 621, in connect
    return self.loaded_dbapi.connect(*cargs, **cparams)
  File "/usr/local/lib/python3.9/site-packages/pymysql/connections.py", line 361, in __init__
    self.connect()
  File "/usr/local/lib/python3.9/site-packages/pymysql/connections.py", line 669, in connect
    self._request_authentication()
  File "/usr/local/lib/python3.9/site-packages/pymysql/connections.py", line 979, in _request_authentication
    auth_packet = _auth.caching_sha2_password_auth(self, auth_packet)
  File "/usr/local/lib/python3.9/site-packages/pymysql/_auth.py", line 267, in caching_sha2_password_auth
    data = sha2_rsa_encrypt(conn.password, conn.salt, conn.server_public_key)
  File "/usr/local/lib/python3.9/site-packages/pymysql/_auth.py", line 144, in sha2_rsa_encrypt
    raise RuntimeError(
RuntimeError: 'cryptography' package is required for sha256_password or caching_sha2_password auth methods
2024-10-25 15:13:04,689 - ERROR - Exception on / [POST]
Traceback (most recent call last):
  File "/usr/local/lib/python3.9/site-packages/flask/app.py", line 1473, in wsgi_app
    response = self.full_dispatch_request()
  File "/usr/local/lib/python3.9/site-packages/flask/app.py", line 882, in full_dispatch_request
    rv = self.handle_user_exception(e)
  File "/usr/local/lib/python3.9/site-packages/flask/app.py", line 880, in full_dispatch_request
    rv = self.dispatch_request()
  File "/usr/local/lib/python3.9/site-packages/flask/app.py", line 865, in dispatch_request
    return self.ensure_sync(self.view_functions[rule.endpoint])(**view_args)  # type: ignore[no-any-return]
  File "/flask/app/main/routes.py", line 12, in index
    form_login()
  File "/flask/app/main/code.py", line 14, in form_login
    user = db.session.query(User).filter_by(email=email).first()
  File "/usr/local/lib/python3.9/site-packages/sqlalchemy/orm/query.py", line 2728, in first
    return self.limit(1)._iter().first()  # type: ignore
  File "/usr/local/lib/python3.9/site-packages/sqlalchemy/orm/query.py", line 2827, in _iter
    result: Union[ScalarResult[_T], Result[_T]] = self.session.execute(
  File "/usr/local/lib/python3.9/site-packages/sqlalchemy/orm/session.py", line 2362, in execute
    return self._execute_internal(
  File "/usr/local/lib/python3.9/site-packages/sqlalchemy/orm/session.py", line 2237, in _execute_internal
    conn = self._connection_for_bind(bind)
  File "/usr/local/lib/python3.9/site-packages/sqlalchemy/orm/session.py", line 2106, in _connection_for_bind
    return trans._connection_for_bind(engine, execution_options)
  File "<string>", line 2, in _connection_for_bind
  File "/usr/local/lib/python3.9/site-packages/sqlalchemy/orm/state_changes.py", line 139, in _go
    ret_value = fn(self, *arg, **kw)
  File "/usr/local/lib/python3.9/site-packages/sqlalchemy/orm/session.py", line 1189, in _connection_for_bind
    conn = bind.connect()
  File "/usr/local/lib/python3.9/site-packages/sqlalchemy/engine/base.py", line 3278, in connect
    return self._connection_cls(self)
  File "/usr/local/lib/python3.9/site-packages/sqlalchemy/engine/base.py", line 146, in __init__
    self._dbapi_connection = engine.raw_connection()
  File "/usr/local/lib/python3.9/site-packages/sqlalchemy/engine/base.py", line 3302, in raw_connection
    return self.pool.connect()
  File "/usr/local/lib/python3.9/site-packages/sqlalchemy/pool/base.py", line 449, in connect
    return _ConnectionFairy._checkout(self)
  File "/usr/local/lib/python3.9/site-packages/sqlalchemy/pool/base.py", line 1263, in _checkout
    fairy = _ConnectionRecord.checkout(pool)
  File "/usr/local/lib/python3.9/site-packages/sqlalchemy/pool/base.py", line 712, in checkout
    rec = pool._do_get()
  File "/usr/local/lib/python3.9/site-packages/sqlalchemy/pool/impl.py", line 180, in _do_get
    self._dec_overflow()
  File "/usr/local/lib/python3.9/site-packages/sqlalchemy/util/langhelpers.py", line 146, in __exit__
    raise exc_value.with_traceback(exc_tb)
  File "/usr/local/lib/python3.9/site-packages/sqlalchemy/pool/impl.py", line 177, in _do_get
    return self._create_connection()
  File "/usr/local/lib/python3.9/site-packages/sqlalchemy/pool/base.py", line 390, in _create_connection
    return _ConnectionRecord(self)
  File "/usr/local/lib/python3.9/site-packages/sqlalchemy/pool/base.py", line 674, in __init__
    self.__connect()
  File "/usr/local/lib/python3.9/site-packages/sqlalchemy/pool/base.py", line 901, in __connect
    pool.logger.debug("Error on connect(): %s", e)
  File "/usr/local/lib/python3.9/site-packages/sqlalchemy/util/langhelpers.py", line 146, in __exit__
    raise exc_value.with_traceback(exc_tb)
  File "/usr/local/lib/python3.9/site-packages/sqlalchemy/pool/base.py", line 896, in __connect
    self.dbapi_connection = connection = pool._invoke_creator(self)
  File "/usr/local/lib/python3.9/site-packages/sqlalchemy/engine/create.py", line 643, in connect
    return dialect.connect(*cargs, **cparams)
  File "/usr/local/lib/python3.9/site-packages/sqlalchemy/engine/default.py", line 621, in connect
    return self.loaded_dbapi.connect(*cargs, **cparams)
  File "/usr/local/lib/python3.9/site-packages/pymysql/connections.py", line 361, in __init__
    self.connect()
  File "/usr/local/lib/python3.9/site-packages/pymysql/connections.py", line 669, in connect
    self._request_authentication()
  File "/usr/local/lib/python3.9/site-packages/pymysql/connections.py", line 979, in _request_authentication
    auth_packet = _auth.caching_sha2_password_auth(self, auth_packet)
  File "/usr/local/lib/python3.9/site-packages/pymysql/_auth.py", line 267, in caching_sha2_password_auth
    data = sha2_rsa_encrypt(conn.password, conn.salt, conn.server_public_key)
  File "/usr/local/lib/python3.9/site-packages/pymysql/_auth.py", line 144, in sha2_rsa_encrypt
    raise RuntimeError(
RuntimeError: 'cryptography' package is required for sha256_password or caching_sha2_password auth methods
2024-10-25 15:17:34,195 - ERROR - Exception on / [POST]
Traceback (most recent call last):
  File "/usr/local/lib/python3.9/site-packages/flask/app.py", line 1473, in wsgi_app
    response = self.full_dispatch_request()
  File "/usr/local/lib/python3.9/site-packages/flask/app.py", line 882, in full_dispatch_request
    rv = self.handle_user_exception(e)
  File "/usr/local/lib/python3.9/site-packages/flask/app.py", line 880, in full_dispatch_request
    rv = self.dispatch_request()
  File "/usr/local/lib/python3.9/site-packages/flask/app.py", line 865, in dispatch_request
    return self.ensure_sync(self.view_functions[rule.endpoint])(**view_args)  # type: ignore[no-any-return]
  File "/flask/app/main/routes.py", line 12, in index
    form_login()
  File "/flask/app/main/code.py", line 14, in form_login
    user = db.session.query(User).filter_by(email=email).first()
  File "/usr/local/lib/python3.9/site-packages/sqlalchemy/orm/query.py", line 2728, in first
    return self.limit(1)._iter().first()  # type: ignore
  File "/usr/local/lib/python3.9/site-packages/sqlalchemy/orm/query.py", line 2827, in _iter
    result: Union[ScalarResult[_T], Result[_T]] = self.session.execute(
  File "/usr/local/lib/python3.9/site-packages/sqlalchemy/orm/session.py", line 2362, in execute
    return self._execute_internal(
  File "/usr/local/lib/python3.9/site-packages/sqlalchemy/orm/session.py", line 2237, in _execute_internal
    conn = self._connection_for_bind(bind)
  File "/usr/local/lib/python3.9/site-packages/sqlalchemy/orm/session.py", line 2106, in _connection_for_bind
    return trans._connection_for_bind(engine, execution_options)
  File "<string>", line 2, in _connection_for_bind
  File "/usr/local/lib/python3.9/site-packages/sqlalchemy/orm/state_changes.py", line 139, in _go
    ret_value = fn(self, *arg, **kw)
  File "/usr/local/lib/python3.9/site-packages/sqlalchemy/orm/session.py", line 1189, in _connection_for_bind
    conn = bind.connect()
  File "/usr/local/lib/python3.9/site-packages/sqlalchemy/engine/base.py", line 3278, in connect
    return self._connection_cls(self)
  File "/usr/local/lib/python3.9/site-packages/sqlalchemy/engine/base.py", line 146, in __init__
    self._dbapi_connection = engine.raw_connection()
  File "/usr/local/lib/python3.9/site-packages/sqlalchemy/engine/base.py", line 3302, in raw_connection
    return self.pool.connect()
  File "/usr/local/lib/python3.9/site-packages/sqlalchemy/pool/base.py", line 449, in connect
    return _ConnectionFairy._checkout(self)
  File "/usr/local/lib/python3.9/site-packages/sqlalchemy/pool/base.py", line 1263, in _checkout
    fairy = _ConnectionRecord.checkout(pool)
  File "/usr/local/lib/python3.9/site-packages/sqlalchemy/pool/base.py", line 712, in checkout
    rec = pool._do_get()
  File "/usr/local/lib/python3.9/site-packages/sqlalchemy/pool/impl.py", line 180, in _do_get
    self._dec_overflow()
  File "/usr/local/lib/python3.9/site-packages/sqlalchemy/util/langhelpers.py", line 146, in __exit__
    raise exc_value.with_traceback(exc_tb)
  File "/usr/local/lib/python3.9/site-packages/sqlalchemy/pool/impl.py", line 177, in _do_get
    return self._create_connection()
  File "/usr/local/lib/python3.9/site-packages/sqlalchemy/pool/base.py", line 390, in _create_connection
    return _ConnectionRecord(self)
  File "/usr/local/lib/python3.9/site-packages/sqlalchemy/pool/base.py", line 674, in __init__
    self.__connect()
  File "/usr/local/lib/python3.9/site-packages/sqlalchemy/pool/base.py", line 901, in __connect
    pool.logger.debug("Error on connect(): %s", e)
  File "/usr/local/lib/python3.9/site-packages/sqlalchemy/util/langhelpers.py", line 146, in __exit__
    raise exc_value.with_traceback(exc_tb)
  File "/usr/local/lib/python3.9/site-packages/sqlalchemy/pool/base.py", line 896, in __connect
    self.dbapi_connection = connection = pool._invoke_creator(self)
  File "/usr/local/lib/python3.9/site-packages/sqlalchemy/engine/create.py", line 643, in connect
    return dialect.connect(*cargs, **cparams)
  File "/usr/local/lib/python3.9/site-packages/sqlalchemy/engine/default.py", line 621, in connect
    return self.loaded_dbapi.connect(*cargs, **cparams)
  File "/usr/local/lib/python3.9/site-packages/pymysql/connections.py", line 361, in __init__
    self.connect()
  File "/usr/local/lib/python3.9/site-packages/pymysql/connections.py", line 669, in connect
    self._request_authentication()
  File "/usr/local/lib/python3.9/site-packages/pymysql/connections.py", line 979, in _request_authentication
    auth_packet = _auth.caching_sha2_password_auth(self, auth_packet)
  File "/usr/local/lib/python3.9/site-packages/pymysql/_auth.py", line 267, in caching_sha2_password_auth
    data = sha2_rsa_encrypt(conn.password, conn.salt, conn.server_public_key)
  File "/usr/local/lib/python3.9/site-packages/pymysql/_auth.py", line 144, in sha2_rsa_encrypt
    raise RuntimeError(
RuntimeError: 'cryptography' package is required for sha256_password or caching_sha2_password auth methods
2024-10-25 15:18:52,466 - ERROR - Exception on / [POST]
Traceback (most recent call last):
  File "/usr/local/lib/python3.9/site-packages/sqlalchemy/engine/base.py", line 1967, in _exec_single_context
    self.dialect.do_execute(
  File "/usr/local/lib/python3.9/site-packages/sqlalchemy/engine/default.py", line 941, in do_execute
    cursor.execute(statement, parameters)
  File "/usr/local/lib/python3.9/site-packages/pymysql/cursors.py", line 153, in execute
    result = self._query(query)
  File "/usr/local/lib/python3.9/site-packages/pymysql/cursors.py", line 322, in _query
    conn.query(q)
  File "/usr/local/lib/python3.9/site-packages/pymysql/connections.py", line 563, in query
    self._affected_rows = self._read_query_result(unbuffered=unbuffered)
  File "/usr/local/lib/python3.9/site-packages/pymysql/connections.py", line 825, in _read_query_result
    result.read()
  File "/usr/local/lib/python3.9/site-packages/pymysql/connections.py", line 1199, in read
    first_packet = self.connection._read_packet()
  File "/usr/local/lib/python3.9/site-packages/pymysql/connections.py", line 775, in _read_packet
    packet.raise_for_error()
  File "/usr/local/lib/python3.9/site-packages/pymysql/protocol.py", line 219, in raise_for_error
    err.raise_mysql_exception(self._data)
  File "/usr/local/lib/python3.9/site-packages/pymysql/err.py", line 150, in raise_mysql_exception
    raise errorclass(errno, errval)
pymysql.err.ProgrammingError: (1146, "Table 'data_dt.user' doesn't exist")

The above exception was the direct cause of the following exception:

Traceback (most recent call last):
  File "/usr/local/lib/python3.9/site-packages/flask/app.py", line 1473, in wsgi_app
    response = self.full_dispatch_request()
  File "/usr/local/lib/python3.9/site-packages/flask/app.py", line 882, in full_dispatch_request
    rv = self.handle_user_exception(e)
  File "/usr/local/lib/python3.9/site-packages/flask/app.py", line 880, in full_dispatch_request
    rv = self.dispatch_request()
  File "/usr/local/lib/python3.9/site-packages/flask/app.py", line 865, in dispatch_request
    return self.ensure_sync(self.view_functions[rule.endpoint])(**view_args)  # type: ignore[no-any-return]
  File "/flask/app/main/routes.py", line 12, in index
    form_login()
  File "/flask/app/main/code.py", line 14, in form_login
    user = db.session.query(User).filter_by(email=email).first()
  File "/usr/local/lib/python3.9/site-packages/sqlalchemy/orm/query.py", line 2728, in first
    return self.limit(1)._iter().first()  # type: ignore
  File "/usr/local/lib/python3.9/site-packages/sqlalchemy/orm/query.py", line 2827, in _iter
    result: Union[ScalarResult[_T], Result[_T]] = self.session.execute(
  File "/usr/local/lib/python3.9/site-packages/sqlalchemy/orm/session.py", line 2362, in execute
    return self._execute_internal(
  File "/usr/local/lib/python3.9/site-packages/sqlalchemy/orm/session.py", line 2247, in _execute_internal
    result: Result[Any] = compile_state_cls.orm_execute_statement(
  File "/usr/local/lib/python3.9/site-packages/sqlalchemy/orm/context.py", line 305, in orm_execute_statement
    result = conn.execute(
  File "/usr/local/lib/python3.9/site-packages/sqlalchemy/engine/base.py", line 1418, in execute
    return meth(
  File "/usr/local/lib/python3.9/site-packages/sqlalchemy/sql/elements.py", line 515, in _execute_on_connection
    return connection._execute_clauseelement(
  File "/usr/local/lib/python3.9/site-packages/sqlalchemy/engine/base.py", line 1640, in _execute_clauseelement
    ret = self._execute_context(
  File "/usr/local/lib/python3.9/site-packages/sqlalchemy/engine/base.py", line 1846, in _execute_context
    return self._exec_single_context(
  File "/usr/local/lib/python3.9/site-packages/sqlalchemy/engine/base.py", line 1986, in _exec_single_context
    self._handle_dbapi_exception(
  File "/usr/local/lib/python3.9/site-packages/sqlalchemy/engine/base.py", line 2355, in _handle_dbapi_exception
    raise sqlalchemy_exception.with_traceback(exc_info[2]) from e
  File "/usr/local/lib/python3.9/site-packages/sqlalchemy/engine/base.py", line 1967, in _exec_single_context
    self.dialect.do_execute(
  File "/usr/local/lib/python3.9/site-packages/sqlalchemy/engine/default.py", line 941, in do_execute
    cursor.execute(statement, parameters)
  File "/usr/local/lib/python3.9/site-packages/pymysql/cursors.py", line 153, in execute
    result = self._query(query)
  File "/usr/local/lib/python3.9/site-packages/pymysql/cursors.py", line 322, in _query
    conn.query(q)
  File "/usr/local/lib/python3.9/site-packages/pymysql/connections.py", line 563, in query
    self._affected_rows = self._read_query_result(unbuffered=unbuffered)
  File "/usr/local/lib/python3.9/site-packages/pymysql/connections.py", line 825, in _read_query_result
    result.read()
  File "/usr/local/lib/python3.9/site-packages/pymysql/connections.py", line 1199, in read
    first_packet = self.connection._read_packet()
  File "/usr/local/lib/python3.9/site-packages/pymysql/connections.py", line 775, in _read_packet
    packet.raise_for_error()
  File "/usr/local/lib/python3.9/site-packages/pymysql/protocol.py", line 219, in raise_for_error
    err.raise_mysql_exception(self._data)
  File "/usr/local/lib/python3.9/site-packages/pymysql/err.py", line 150, in raise_mysql_exception
    raise errorclass(errno, errval)
sqlalchemy.exc.ProgrammingError: (pymysql.err.ProgrammingError) (1146, "Table 'data_dt.user' doesn't exist")
[SQL: SELECT user.id AS user_id, user.email AS user_email, user.name AS user_name, user.pwd_hash AS user_pwd_hash 
FROM user 
WHERE user.email = %(email_1)s 
 LIMIT %(param_1)s]
[parameters: {'email_1': 'qwe1474376@gmail.com', 'param_1': 1}]
(Background on this error at: https://sqlalche.me/e/20/f405)
2024-10-25 15:18:56,732 - ERROR - Exception on / [POST]
Traceback (most recent call last):
  File "/usr/local/lib/python3.9/site-packages/sqlalchemy/engine/base.py", line 1967, in _exec_single_context
    self.dialect.do_execute(
  File "/usr/local/lib/python3.9/site-packages/sqlalchemy/engine/default.py", line 941, in do_execute
    cursor.execute(statement, parameters)
  File "/usr/local/lib/python3.9/site-packages/pymysql/cursors.py", line 153, in execute
    result = self._query(query)
  File "/usr/local/lib/python3.9/site-packages/pymysql/cursors.py", line 322, in _query
    conn.query(q)
  File "/usr/local/lib/python3.9/site-packages/pymysql/connections.py", line 563, in query
    self._affected_rows = self._read_query_result(unbuffered=unbuffered)
  File "/usr/local/lib/python3.9/site-packages/pymysql/connections.py", line 825, in _read_query_result
    result.read()
  File "/usr/local/lib/python3.9/site-packages/pymysql/connections.py", line 1199, in read
    first_packet = self.connection._read_packet()
  File "/usr/local/lib/python3.9/site-packages/pymysql/connections.py", line 775, in _read_packet
    packet.raise_for_error()
  File "/usr/local/lib/python3.9/site-packages/pymysql/protocol.py", line 219, in raise_for_error
    err.raise_mysql_exception(self._data)
  File "/usr/local/lib/python3.9/site-packages/pymysql/err.py", line 150, in raise_mysql_exception
    raise errorclass(errno, errval)
pymysql.err.ProgrammingError: (1146, "Table 'data_dt.user' doesn't exist")

The above exception was the direct cause of the following exception:

Traceback (most recent call last):
  File "/usr/local/lib/python3.9/site-packages/flask/app.py", line 1473, in wsgi_app
    response = self.full_dispatch_request()
  File "/usr/local/lib/python3.9/site-packages/flask/app.py", line 882, in full_dispatch_request
    rv = self.handle_user_exception(e)
  File "/usr/local/lib/python3.9/site-packages/flask/app.py", line 880, in full_dispatch_request
    rv = self.dispatch_request()
  File "/usr/local/lib/python3.9/site-packages/flask/app.py", line 865, in dispatch_request
    return self.ensure_sync(self.view_functions[rule.endpoint])(**view_args)  # type: ignore[no-any-return]
  File "/flask/app/main/routes.py", line 12, in index
    form_login()
  File "/flask/app/main/code.py", line 14, in form_login
    user = db.session.query(User).filter_by(email=email).first()
  File "/usr/local/lib/python3.9/site-packages/sqlalchemy/orm/query.py", line 2728, in first
    return self.limit(1)._iter().first()  # type: ignore
  File "/usr/local/lib/python3.9/site-packages/sqlalchemy/orm/query.py", line 2827, in _iter
    result: Union[ScalarResult[_T], Result[_T]] = self.session.execute(
  File "/usr/local/lib/python3.9/site-packages/sqlalchemy/orm/session.py", line 2362, in execute
    return self._execute_internal(
  File "/usr/local/lib/python3.9/site-packages/sqlalchemy/orm/session.py", line 2247, in _execute_internal
    result: Result[Any] = compile_state_cls.orm_execute_statement(
  File "/usr/local/lib/python3.9/site-packages/sqlalchemy/orm/context.py", line 305, in orm_execute_statement
    result = conn.execute(
  File "/usr/local/lib/python3.9/site-packages/sqlalchemy/engine/base.py", line 1418, in execute
    return meth(
  File "/usr/local/lib/python3.9/site-packages/sqlalchemy/sql/elements.py", line 515, in _execute_on_connection
    return connection._execute_clauseelement(
  File "/usr/local/lib/python3.9/site-packages/sqlalchemy/engine/base.py", line 1640, in _execute_clauseelement
    ret = self._execute_context(
  File "/usr/local/lib/python3.9/site-packages/sqlalchemy/engine/base.py", line 1846, in _execute_context
    return self._exec_single_context(
  File "/usr/local/lib/python3.9/site-packages/sqlalchemy/engine/base.py", line 1986, in _exec_single_context
    self._handle_dbapi_exception(
  File "/usr/local/lib/python3.9/site-packages/sqlalchemy/engine/base.py", line 2355, in _handle_dbapi_exception
    raise sqlalchemy_exception.with_traceback(exc_info[2]) from e
  File "/usr/local/lib/python3.9/site-packages/sqlalchemy/engine/base.py", line 1967, in _exec_single_context
    self.dialect.do_execute(
  File "/usr/local/lib/python3.9/site-packages/sqlalchemy/engine/default.py", line 941, in do_execute
    cursor.execute(statement, parameters)
  File "/usr/local/lib/python3.9/site-packages/pymysql/cursors.py", line 153, in execute
    result = self._query(query)
  File "/usr/local/lib/python3.9/site-packages/pymysql/cursors.py", line 322, in _query
    conn.query(q)
  File "/usr/local/lib/python3.9/site-packages/pymysql/connections.py", line 563, in query
    self._affected_rows = self._read_query_result(unbuffered=unbuffered)
  File "/usr/local/lib/python3.9/site-packages/pymysql/connections.py", line 825, in _read_query_result
    result.read()
  File "/usr/local/lib/python3.9/site-packages/pymysql/connections.py", line 1199, in read
    first_packet = self.connection._read_packet()
  File "/usr/local/lib/python3.9/site-packages/pymysql/connections.py", line 775, in _read_packet
    packet.raise_for_error()
  File "/usr/local/lib/python3.9/site-packages/pymysql/protocol.py", line 219, in raise_for_error
    err.raise_mysql_exception(self._data)
  File "/usr/local/lib/python3.9/site-packages/pymysql/err.py", line 150, in raise_mysql_exception
    raise errorclass(errno, errval)
sqlalchemy.exc.ProgrammingError: (pymysql.err.ProgrammingError) (1146, "Table 'data_dt.user' doesn't exist")
[SQL: SELECT user.id AS user_id, user.email AS user_email, user.name AS user_name, user.pwd_hash AS user_pwd_hash 
FROM user 
WHERE user.email = %(email_1)s 
 LIMIT %(param_1)s]
[parameters: {'email_1': 'qwe1474376@gmail.com', 'param_1': 1}]
(Background on this error at: https://sqlalche.me/e/20/f405)
2024-10-25 15:19:00,017 - ERROR - Exception on / [POST]
Traceback (most recent call last):
  File "/usr/local/lib/python3.9/site-packages/sqlalchemy/engine/base.py", line 1967, in _exec_single_context
    self.dialect.do_execute(
  File "/usr/local/lib/python3.9/site-packages/sqlalchemy/engine/default.py", line 941, in do_execute
    cursor.execute(statement, parameters)
  File "/usr/local/lib/python3.9/site-packages/pymysql/cursors.py", line 153, in execute
    result = self._query(query)
  File "/usr/local/lib/python3.9/site-packages/pymysql/cursors.py", line 322, in _query
    conn.query(q)
  File "/usr/local/lib/python3.9/site-packages/pymysql/connections.py", line 563, in query
    self._affected_rows = self._read_query_result(unbuffered=unbuffered)
  File "/usr/local/lib/python3.9/site-packages/pymysql/connections.py", line 825, in _read_query_result
    result.read()
  File "/usr/local/lib/python3.9/site-packages/pymysql/connections.py", line 1199, in read
    first_packet = self.connection._read_packet()
  File "/usr/local/lib/python3.9/site-packages/pymysql/connections.py", line 775, in _read_packet
    packet.raise_for_error()
  File "/usr/local/lib/python3.9/site-packages/pymysql/protocol.py", line 219, in raise_for_error
    err.raise_mysql_exception(self._data)
  File "/usr/local/lib/python3.9/site-packages/pymysql/err.py", line 150, in raise_mysql_exception
    raise errorclass(errno, errval)
pymysql.err.ProgrammingError: (1146, "Table 'data_dt.user' doesn't exist")

The above exception was the direct cause of the following exception:

Traceback (most recent call last):
  File "/usr/local/lib/python3.9/site-packages/flask/app.py", line 1473, in wsgi_app
    response = self.full_dispatch_request()
  File "/usr/local/lib/python3.9/site-packages/flask/app.py", line 882, in full_dispatch_request
    rv = self.handle_user_exception(e)
  File "/usr/local/lib/python3.9/site-packages/flask/app.py", line 880, in full_dispatch_request
    rv = self.dispatch_request()
  File "/usr/local/lib/python3.9/site-packages/flask/app.py", line 865, in dispatch_request
    return self.ensure_sync(self.view_functions[rule.endpoint])(**view_args)  # type: ignore[no-any-return]
  File "/flask/app/main/routes.py", line 12, in index
    form_login()
  File "/flask/app/main/code.py", line 14, in form_login
    user = db.session.query(User).filter_by(email=email).first()
  File "/usr/local/lib/python3.9/site-packages/sqlalchemy/orm/query.py", line 2728, in first
    return self.limit(1)._iter().first()  # type: ignore
  File "/usr/local/lib/python3.9/site-packages/sqlalchemy/orm/query.py", line 2827, in _iter
    result: Union[ScalarResult[_T], Result[_T]] = self.session.execute(
  File "/usr/local/lib/python3.9/site-packages/sqlalchemy/orm/session.py", line 2362, in execute
    return self._execute_internal(
  File "/usr/local/lib/python3.9/site-packages/sqlalchemy/orm/session.py", line 2247, in _execute_internal
    result: Result[Any] = compile_state_cls.orm_execute_statement(
  File "/usr/local/lib/python3.9/site-packages/sqlalchemy/orm/context.py", line 305, in orm_execute_statement
    result = conn.execute(
  File "/usr/local/lib/python3.9/site-packages/sqlalchemy/engine/base.py", line 1418, in execute
    return meth(
  File "/usr/local/lib/python3.9/site-packages/sqlalchemy/sql/elements.py", line 515, in _execute_on_connection
    return connection._execute_clauseelement(
  File "/usr/local/lib/python3.9/site-packages/sqlalchemy/engine/base.py", line 1640, in _execute_clauseelement
    ret = self._execute_context(
  File "/usr/local/lib/python3.9/site-packages/sqlalchemy/engine/base.py", line 1846, in _execute_context
    return self._exec_single_context(
  File "/usr/local/lib/python3.9/site-packages/sqlalchemy/engine/base.py", line 1986, in _exec_single_context
    self._handle_dbapi_exception(
  File "/usr/local/lib/python3.9/site-packages/sqlalchemy/engine/base.py", line 2355, in _handle_dbapi_exception
    raise sqlalchemy_exception.with_traceback(exc_info[2]) from e
  File "/usr/local/lib/python3.9/site-packages/sqlalchemy/engine/base.py", line 1967, in _exec_single_context
    self.dialect.do_execute(
  File "/usr/local/lib/python3.9/site-packages/sqlalchemy/engine/default.py", line 941, in do_execute
    cursor.execute(statement, parameters)
  File "/usr/local/lib/python3.9/site-packages/pymysql/cursors.py", line 153, in execute
    result = self._query(query)
  File "/usr/local/lib/python3.9/site-packages/pymysql/cursors.py", line 322, in _query
    conn.query(q)
  File "/usr/local/lib/python3.9/site-packages/pymysql/connections.py", line 563, in query
    self._affected_rows = self._read_query_result(unbuffered=unbuffered)
  File "/usr/local/lib/python3.9/site-packages/pymysql/connections.py", line 825, in _read_query_result
    result.read()
  File "/usr/local/lib/python3.9/site-packages/pymysql/connections.py", line 1199, in read
    first_packet = self.connection._read_packet()
  File "/usr/local/lib/python3.9/site-packages/pymysql/connections.py", line 775, in _read_packet
    packet.raise_for_error()
  File "/usr/local/lib/python3.9/site-packages/pymysql/protocol.py", line 219, in raise_for_error
    err.raise_mysql_exception(self._data)
  File "/usr/local/lib/python3.9/site-packages/pymysql/err.py", line 150, in raise_mysql_exception
    raise errorclass(errno, errval)
sqlalchemy.exc.ProgrammingError: (pymysql.err.ProgrammingError) (1146, "Table 'data_dt.user' doesn't exist")
[SQL: SELECT user.id AS user_id, user.email AS user_email, user.name AS user_name, user.pwd_hash AS user_pwd_hash 
FROM user 
WHERE user.email = %(email_1)s 
 LIMIT %(param_1)s]
[parameters: {'email_1': 'qwe1474376@gmail.com', 'param_1': 1}]
(Background on this error at: https://sqlalche.me/e/20/f405)
2024-10-25 15:19:11,715 - ERROR - Exception on / [POST]
Traceback (most recent call last):
  File "/usr/local/lib/python3.9/site-packages/sqlalchemy/engine/base.py", line 1967, in _exec_single_context
    self.dialect.do_execute(
  File "/usr/local/lib/python3.9/site-packages/sqlalchemy/engine/default.py", line 941, in do_execute
    cursor.execute(statement, parameters)
  File "/usr/local/lib/python3.9/site-packages/pymysql/cursors.py", line 153, in execute
    result = self._query(query)
  File "/usr/local/lib/python3.9/site-packages/pymysql/cursors.py", line 322, in _query
    conn.query(q)
  File "/usr/local/lib/python3.9/site-packages/pymysql/connections.py", line 563, in query
    self._affected_rows = self._read_query_result(unbuffered=unbuffered)
  File "/usr/local/lib/python3.9/site-packages/pymysql/connections.py", line 825, in _read_query_result
    result.read()
  File "/usr/local/lib/python3.9/site-packages/pymysql/connections.py", line 1199, in read
    first_packet = self.connection._read_packet()
  File "/usr/local/lib/python3.9/site-packages/pymysql/connections.py", line 775, in _read_packet
    packet.raise_for_error()
  File "/usr/local/lib/python3.9/site-packages/pymysql/protocol.py", line 219, in raise_for_error
    err.raise_mysql_exception(self._data)
  File "/usr/local/lib/python3.9/site-packages/pymysql/err.py", line 150, in raise_mysql_exception
    raise errorclass(errno, errval)
pymysql.err.ProgrammingError: (1146, "Table 'data_dt.user' doesn't exist")

The above exception was the direct cause of the following exception:

Traceback (most recent call last):
  File "/usr/local/lib/python3.9/site-packages/flask/app.py", line 1473, in wsgi_app
    response = self.full_dispatch_request()
  File "/usr/local/lib/python3.9/site-packages/flask/app.py", line 882, in full_dispatch_request
    rv = self.handle_user_exception(e)
  File "/usr/local/lib/python3.9/site-packages/flask/app.py", line 880, in full_dispatch_request
    rv = self.dispatch_request()
  File "/usr/local/lib/python3.9/site-packages/flask/app.py", line 865, in dispatch_request
    return self.ensure_sync(self.view_functions[rule.endpoint])(**view_args)  # type: ignore[no-any-return]
  File "/flask/app/main/routes.py", line 12, in index
    form_login()
  File "/flask/app/main/code.py", line 14, in form_login
    user = db.session.query(User).filter_by(email=email).first()
  File "/usr/local/lib/python3.9/site-packages/sqlalchemy/orm/query.py", line 2728, in first
    return self.limit(1)._iter().first()  # type: ignore
  File "/usr/local/lib/python3.9/site-packages/sqlalchemy/orm/query.py", line 2827, in _iter
    result: Union[ScalarResult[_T], Result[_T]] = self.session.execute(
  File "/usr/local/lib/python3.9/site-packages/sqlalchemy/orm/session.py", line 2362, in execute
    return self._execute_internal(
  File "/usr/local/lib/python3.9/site-packages/sqlalchemy/orm/session.py", line 2247, in _execute_internal
    result: Result[Any] = compile_state_cls.orm_execute_statement(
  File "/usr/local/lib/python3.9/site-packages/sqlalchemy/orm/context.py", line 305, in orm_execute_statement
    result = conn.execute(
  File "/usr/local/lib/python3.9/site-packages/sqlalchemy/engine/base.py", line 1418, in execute
    return meth(
  File "/usr/local/lib/python3.9/site-packages/sqlalchemy/sql/elements.py", line 515, in _execute_on_connection
    return connection._execute_clauseelement(
  File "/usr/local/lib/python3.9/site-packages/sqlalchemy/engine/base.py", line 1640, in _execute_clauseelement
    ret = self._execute_context(
  File "/usr/local/lib/python3.9/site-packages/sqlalchemy/engine/base.py", line 1846, in _execute_context
    return self._exec_single_context(
  File "/usr/local/lib/python3.9/site-packages/sqlalchemy/engine/base.py", line 1986, in _exec_single_context
    self._handle_dbapi_exception(
  File "/usr/local/lib/python3.9/site-packages/sqlalchemy/engine/base.py", line 2355, in _handle_dbapi_exception
    raise sqlalchemy_exception.with_traceback(exc_info[2]) from e
  File "/usr/local/lib/python3.9/site-packages/sqlalchemy/engine/base.py", line 1967, in _exec_single_context
    self.dialect.do_execute(
  File "/usr/local/lib/python3.9/site-packages/sqlalchemy/engine/default.py", line 941, in do_execute
    cursor.execute(statement, parameters)
  File "/usr/local/lib/python3.9/site-packages/pymysql/cursors.py", line 153, in execute
    result = self._query(query)
  File "/usr/local/lib/python3.9/site-packages/pymysql/cursors.py", line 322, in _query
    conn.query(q)
  File "/usr/local/lib/python3.9/site-packages/pymysql/connections.py", line 563, in query
    self._affected_rows = self._read_query_result(unbuffered=unbuffered)
  File "/usr/local/lib/python3.9/site-packages/pymysql/connections.py", line 825, in _read_query_result
    result.read()
  File "/usr/local/lib/python3.9/site-packages/pymysql/connections.py", line 1199, in read
    first_packet = self.connection._read_packet()
  File "/usr/local/lib/python3.9/site-packages/pymysql/connections.py", line 775, in _read_packet
    packet.raise_for_error()
  File "/usr/local/lib/python3.9/site-packages/pymysql/protocol.py", line 219, in raise_for_error
    err.raise_mysql_exception(self._data)
  File "/usr/local/lib/python3.9/site-packages/pymysql/err.py", line 150, in raise_mysql_exception
    raise errorclass(errno, errval)
sqlalchemy.exc.ProgrammingError: (pymysql.err.ProgrammingError) (1146, "Table 'data_dt.user' doesn't exist")
[SQL: SELECT user.id AS user_id, user.email AS user_email, user.name AS user_name, user.pwd_hash AS user_pwd_hash 
FROM user 
WHERE user.email = %(email_1)s 
 LIMIT %(param_1)s]
[parameters: {'email_1': 'qwe1474376@gmail.com', 'param_1': 1}]
(Background on this error at: https://sqlalche.me/e/20/f405)
2024-10-25 15:19:35,595 - ERROR - Exception on / [POST]
Traceback (most recent call last):
  File "/usr/local/lib/python3.9/site-packages/sqlalchemy/engine/base.py", line 1967, in _exec_single_context
    self.dialect.do_execute(
  File "/usr/local/lib/python3.9/site-packages/sqlalchemy/engine/default.py", line 941, in do_execute
    cursor.execute(statement, parameters)
  File "/usr/local/lib/python3.9/site-packages/pymysql/cursors.py", line 153, in execute
    result = self._query(query)
  File "/usr/local/lib/python3.9/site-packages/pymysql/cursors.py", line 322, in _query
    conn.query(q)
  File "/usr/local/lib/python3.9/site-packages/pymysql/connections.py", line 563, in query
    self._affected_rows = self._read_query_result(unbuffered=unbuffered)
  File "/usr/local/lib/python3.9/site-packages/pymysql/connections.py", line 825, in _read_query_result
    result.read()
  File "/usr/local/lib/python3.9/site-packages/pymysql/connections.py", line 1199, in read
    first_packet = self.connection._read_packet()
  File "/usr/local/lib/python3.9/site-packages/pymysql/connections.py", line 775, in _read_packet
    packet.raise_for_error()
  File "/usr/local/lib/python3.9/site-packages/pymysql/protocol.py", line 219, in raise_for_error
    err.raise_mysql_exception(self._data)
  File "/usr/local/lib/python3.9/site-packages/pymysql/err.py", line 150, in raise_mysql_exception
    raise errorclass(errno, errval)
pymysql.err.ProgrammingError: (1146, "Table 'data_dt.user' doesn't exist")

The above exception was the direct cause of the following exception:

Traceback (most recent call last):
  File "/usr/local/lib/python3.9/site-packages/flask/app.py", line 1473, in wsgi_app
    response = self.full_dispatch_request()
  File "/usr/local/lib/python3.9/site-packages/flask/app.py", line 882, in full_dispatch_request
    rv = self.handle_user_exception(e)
  File "/usr/local/lib/python3.9/site-packages/flask/app.py", line 880, in full_dispatch_request
    rv = self.dispatch_request()
  File "/usr/local/lib/python3.9/site-packages/flask/app.py", line 865, in dispatch_request
    return self.ensure_sync(self.view_functions[rule.endpoint])(**view_args)  # type: ignore[no-any-return]
  File "/flask/app/main/routes.py", line 12, in index
    form_login()
  File "/flask/app/main/code.py", line 14, in form_login
    user = db.session.query(User).filter_by(email=email).first()
  File "/usr/local/lib/python3.9/site-packages/sqlalchemy/orm/query.py", line 2728, in first
    return self.limit(1)._iter().first()  # type: ignore
  File "/usr/local/lib/python3.9/site-packages/sqlalchemy/orm/query.py", line 2827, in _iter
    result: Union[ScalarResult[_T], Result[_T]] = self.session.execute(
  File "/usr/local/lib/python3.9/site-packages/sqlalchemy/orm/session.py", line 2362, in execute
    return self._execute_internal(
  File "/usr/local/lib/python3.9/site-packages/sqlalchemy/orm/session.py", line 2247, in _execute_internal
    result: Result[Any] = compile_state_cls.orm_execute_statement(
  File "/usr/local/lib/python3.9/site-packages/sqlalchemy/orm/context.py", line 305, in orm_execute_statement
    result = conn.execute(
  File "/usr/local/lib/python3.9/site-packages/sqlalchemy/engine/base.py", line 1418, in execute
    return meth(
  File "/usr/local/lib/python3.9/site-packages/sqlalchemy/sql/elements.py", line 515, in _execute_on_connection
    return connection._execute_clauseelement(
  File "/usr/local/lib/python3.9/site-packages/sqlalchemy/engine/base.py", line 1640, in _execute_clauseelement
    ret = self._execute_context(
  File "/usr/local/lib/python3.9/site-packages/sqlalchemy/engine/base.py", line 1846, in _execute_context
    return self._exec_single_context(
  File "/usr/local/lib/python3.9/site-packages/sqlalchemy/engine/base.py", line 1986, in _exec_single_context
    self._handle_dbapi_exception(
  File "/usr/local/lib/python3.9/site-packages/sqlalchemy/engine/base.py", line 2355, in _handle_dbapi_exception
    raise sqlalchemy_exception.with_traceback(exc_info[2]) from e
  File "/usr/local/lib/python3.9/site-packages/sqlalchemy/engine/base.py", line 1967, in _exec_single_context
    self.dialect.do_execute(
  File "/usr/local/lib/python3.9/site-packages/sqlalchemy/engine/default.py", line 941, in do_execute
    cursor.execute(statement, parameters)
  File "/usr/local/lib/python3.9/site-packages/pymysql/cursors.py", line 153, in execute
    result = self._query(query)
  File "/usr/local/lib/python3.9/site-packages/pymysql/cursors.py", line 322, in _query
    conn.query(q)
  File "/usr/local/lib/python3.9/site-packages/pymysql/connections.py", line 563, in query
    self._affected_rows = self._read_query_result(unbuffered=unbuffered)
  File "/usr/local/lib/python3.9/site-packages/pymysql/connections.py", line 825, in _read_query_result
    result.read()
  File "/usr/local/lib/python3.9/site-packages/pymysql/connections.py", line 1199, in read
    first_packet = self.connection._read_packet()
  File "/usr/local/lib/python3.9/site-packages/pymysql/connections.py", line 775, in _read_packet
    packet.raise_for_error()
  File "/usr/local/lib/python3.9/site-packages/pymysql/protocol.py", line 219, in raise_for_error
    err.raise_mysql_exception(self._data)
  File "/usr/local/lib/python3.9/site-packages/pymysql/err.py", line 150, in raise_mysql_exception
    raise errorclass(errno, errval)
sqlalchemy.exc.ProgrammingError: (pymysql.err.ProgrammingError) (1146, "Table 'data_dt.user' doesn't exist")
[SQL: SELECT user.id AS user_id, user.email AS user_email, user.name AS user_name, user.pwd_hash AS user_pwd_hash 
FROM user 
WHERE user.email = %(email_1)s 
 LIMIT %(param_1)s]
[parameters: {'email_1': 'qwe1474376@gmail.com', 'param_1': 1}]
(Background on this error at: https://sqlalche.me/e/20/f405)
